错误是任何程序都必然遇到的异常情况，如果没有处理或者处理得不好，那么应用的使用体验将大打折扣，对于程序员来说则是工作质量欠优。

但是错误处理往往也会被过度使用，导致关键的诊断信息被埋没。我试图用本文的篇幅来为大家展现 ECMAScript 规范中错误的全景，以及如何在日常使用中得当地处理错误。

错误的类型与结构
--------

在 JavaScript 中抛出的错误可以分成两类：`早期错误（Early Error）`和`运行时错误（Runtime Error）`。

早期错误是在 JavaScript 代码解释的过程中抛出的，典型的就是语法错误（`SyntaxError`）；而运行时错误则显然就是在运行期间抛出的错误，如主动 `throw` 的错误。

在具体的对象实现上，首先是基础类 `Error`，既可以直接构造错误对象，也可以继承来实现自己的错误类。

在过去，Error 只支持一个字符串参数 _message_，现在，又开始支持一个新的聚合参数 _option_，目前只有里面的 **cause** 被使用：

    const err = new Error('test error', {
        cause: otherError,
    });
    

**cause** 代表了这个错误是由哪个其它错误所引起的，比如我们定义了一个自定义错误叫做 ParseError，只要 parse 函数错误就抛出这个异常，但是错误的具体原因可能有好多种，那么就可以用 **cause** 关联起来。

如果问具有怎么有什么的话，你可以直接在错误对象上访问得到：

    err.cause
    

可以补充到错误日志中，增加判断和诊断错误的信息量。

> 💡 目前只有比较新的浏览器才支持 cause：Chrome >= 93，Safari >= 15，Firefox >= 91，但是无所谓，因为旧版本会忽略掉多余的参数。

Error 还有一个特性就是它不需要 new 依然可以构造出错误对象。以下两种写法是等价的：

    new Error()
    Error()
    

因此，鉴于节省代码量的考虑，我建议 **`创建 Error 对象时始终省略操作符号 new`**。这一特性还适用于所有 ECMAScript 定义的内置错误类型，至于你的自定义错误类能不能这样写，取决于写法，至少说 class 方式肯定是不可以的。

除了 cause，Error 对象上最常见的两个属性是 **name** 和 **message**，特别是后者，承载了主要信息量。事实上，这两个属性本来是定义在原型对象 `Error.prototype` 上的，只是在创建 Error 对象时，也会在对象本身上创建一个 message 属性，它和 cause 一样，也是**不可枚举的**。

    Object.getOwnPropertyDescriptor(new Error('test'), 'message');
    // {
    //  value: 'test',
    //  writable: true,
    //  enumerable: false,
    //  configurable: true
    //}
    

而 `name` 并不会在对象本身上定义，还是取的原型对象上的值。因此，**`不要试图解构 Error 对象`**，因为啥也取不到：

    console.log({ ...new Error('test') }) // {}
    

`name` 用于标识不同的 Error 类型，ECMAScript 定义了几种 Error 的子类，包括 `EvalError`、`RangeError`、`ReferenceError`、`SyntaxError`、`TypeError` 和 `URIError`。

1.  `EvalError` 自从 ES5 开始就不再被使用了，`eval` 函数不会抛出它，目前仅留作向 ES3 兼容。
2.  `RangeError` 都是在数字不在合法范围内时抛出的，典型案例：

    // Number.prototype.toExponential 参数小于0或者大于100
    (5).toExponential(101)
    // Number.prototype.toFixed 参数小于0或者大于100
    (5).toFixed(101)
    // Number.prototype.toPrecision 参数小于1或者大于100
    (5).toPrecision(101)
    // Number.prototype.toString 参数不是2-36的数
    (5).toString(37)
    // Date.prototype.toISOString 时间戳为无穷
    new Date(Infinity).toISOString()
    // String.fromCodePoint 参数不是0-0x10FFFF之间的正整数
    String.fromCodePoint(1.2)
    

3.  `ReferenceError` 的异常都是出在变量引用上。

    // 找不到变量
    a + b
    // TDZ
    a + 1
    let a = 0;
    

4.  `SyntaxError` 不必多说，它常常是早期错误。
5.  `TypeError` 常常用于类型方面的错误，例如：

    // 修改const
    const a = 0;
    a = 1;
    // 不用 new 创建 Map、Set
    Map();
    Set();
    // Symbol.toPrimitive 返回非 Primitive 类型
    const obj = { [Symbol.toPrimitive]() { return {}; } };
    `${obj}`
    

我们自己编写的代码也常常可以使用 TypeError，比如你检验发现参数或者指令不符合预期的类型时。

6.  `URIError` 会在 `encodeURIComponent`、`encodeURI`、`decodeURIComponent`、`decodeURI` 这 4 个函数中抛出，一般是遭遇到了不合法的数据，这里我们可以拓展一下在之前字符串那一章没有提到的知识。

我们知道有些字符用一个码元（Code Unit，16位，2字节）表示不了，在 UTF-16 中要占用两个码元，那么这两个码元的各自值是多少呢？

还是以`𠯿`为例，它的 Unicode 点位是**0x20BFF**，那么它是不是就存储成下面这样呢？

![](https://p3-juejin.byteimg.com/tos-cn-i-k3u1fbpfcp/c134dc8f9fb24638a571344ed35cdb49~tplv-k3u1fbpfcp-jj-mark:1600:0:0:0:q75.jpg#?w=964&h=164&s=25436&e=png&b=bcdeb0)

**当然不是！** 否则我们怎么知道这两个字节是放在一起解析的，而不是一个一个解析的。前面的 0x20 刚好是我们最常用的空白符。所以**从这里大家应该就能体会到，为什么有了 Unicode 字符集之后，还要有 UTF-8、UTF-16、UTF-32 这些编码方案吧**。

UTF-16 是这样处理的，设有 Unicode 点位值 U：

1.  首个码元值的计算法则：`C1=Math.floor((U - 0x10000) / 0x400) + 0xD800`；
2.  第二个码元值的计算法则：`C2=((U - 0x10000) % 0x400) + 0xDC00`。

由于 Unicode 的范围是 `0~0x10FFFF`，因此最后 C1 的范围就是 `0xD800~0xDBFF`，而 C2 的范围是 `0xDC00～0xDFFF`，它们一定是成对出现的，如果没有成对，就是非法的，上述 4 个函数在遇到这种情况的时候就会抛出 `URIError`。

用“𠯿”验证一下：

    const U = "𠯿".codePointAt(0);
    
    const C1 = Math.floor((U - 0x10000) / 0x400) + 0xD800;
    const C2 = ((U - 0x10000) % 0x400) + 0xDC00;
    
    console.log("𠯿".charCodeAt(0) === C1); // true
    console.log("𠯿".charCodeAt(1) === C2); // true
    

因此它真正的存储数据是：

![](https://p9-juejin.byteimg.com/tos-cn-i-k3u1fbpfcp/f8987f1d3aa14c199232bb317822e37a~tplv-k3u1fbpfcp-jj-mark:1600:0:0:0:q75.image#?w=964&h=164&s=24884&e=png&b=bcdeb0)

那么如何用两个码元反向计算 Unicode 点位值呢？一个公式即可：

    const U = (C1 - 0xD800) × 0x400 + (C2 - 0xDC00) + 0x10000;
    

大家不妨试一试。在官方术语中，C1 称之为 `leading surrogate`，C2 称之为 `trailing surrogate`，有兴趣可以作进一步了解。

总之，浏览器正常输入的字符串传入 encodeURIComponent 肯定是没问题，如果字符串来自于 CodePoint 的构造，那么还是需要关注一下是否会产生 `URIError`。

除了上述这些错误类型之外，不同的 JavaScript 引擎可能还会定义额外的错误，比如 V8 定义了 `WasmCompileError`、`WasmLinkError`、`WasmRuntimeError`。这些引擎内部实现的错误统一称之为 **`NativeError`**。

虽然有这么多种类，但不用指望它们会提供额外的什么信息，它们和基类 Error 的区别也仅仅在于名字不同。我们在消费错误对象的时候，可以先以 `name` 来先进行一波分类，然后再去看 `message`。

需要注意的是，对这些子类，`name` 也是定义在原型上而不是对象本身，因此，如果你想实现一个自定义类，参考 `NativeError` 的结构，应该是这样的：

    class MyError extends Error {}
    
    Object.defineProperty(MyError.prototype, 'name', {
        value: 'MyError',
        writable: true,
        enumerable: false,
        configurable: true
    });
    

> 💡在有的环境中，Error 对象上可能还存在着 `stack`、`fileName`、`lineNumber`、`columnNumber` 等属性，这些都不是规范定义的，引擎对它们的实现可能不尽相同，可以使用它们，但要小心，做好充足的回退策略。

聚合错误
----

ES2021 引入了 Error 的一个新的子类：`AggregateError`。功能和它的名字一样，将多个错误聚合在一起，目前只有 `Promise.any` 会抛出这个错误类型，当然你也可以手动创建这样一个实例。

和前面提到的 Error 后代不同，`AggregateError` 在构造参数上有明显的变化：

    new AggregateError([
        error1,
        error2
    ], 'test message');
    

在常规参数（包括 message 和 options.cause）的前面，`AggregateError` 需要一个容纳一个或多个 Error 对象的迭代器。是的，该参数可以不是数组，甚至其中每个成员也可以不是 Error 类型，cause 也是如此。

> 💡 不过，`AggregateError` 对象在自身上定义 `errors` 属性时还会是一个数组类型，并不是直接引用的构造参数对象。

当 `Promise.any` 参数中的所有 Promise 都被 rejected 后，我们就会得到一个 `AggregateError`：

    Promise.any([
        Promise.reject(1),
        Promise.reject(2),
        Promise.reject(3),
    ]).catch(err => {
        console.log(err); // [AggregateError: All promises were rejected]
        console.log(err.errors); // [ 1, 2, 3 ]
    });
    

`Promise.any` 和 `AggregateError` 一起都是从 Chrome 85，Safari 14 以及 Firefox 79 开始被支持，不过 core-js 都提供相应的 _polyfill_。

单独使用 `AggregateError` 的话，可以用 `typeof` 判断存在与否再使用。

错误捕获
----

常规的错误捕获手段自然就是 `try...catch...finally`，而且适用于 `await` 异步代码。如果大家细心的话，在写 TypeScript 的时候，对 `catch` 参数的声明推荐类型是 `unknown`：

    try {
     // ...
    } catch(err: unknown) {}
    

这是因为，就像 Error 的 `cause` 以及 AggregateError 的 `errors` 参数一样，JavaScript 中抛出的也可以不是 Error 的实例，任意类型都可以：

    throw "Fake Exception";
    

所以我们 `catch` 的时候自然也不一定是什么类型，用 `unknown` 会更保险。鉴于语义化和处理上的方便，还是更建议 **`始终 throw Error 类型的对象`**，而不是其它。

在异步执行流中，错误处理也有额外的方式，一种是早些年间的 `error callback`，现在 Node.js 仍然有大量 API 是这种风格：

    import fs from 'fs';
    
    fs.readFile('./song.mp3', (err, data) => {
    
    });
    

它的特点是只有 err 为空时（即没有发生错误时），data 才有意义。弊端也很明显，一旦这个 callback 函数意外地抛出了异常，往往是没有被捕获的。

异步编程模式发展到 Promise 后，链式调用 then/catch 就成了必备异常处理手段。一般有以下两种写法：

    doSomething().then(handleResult, handleException);
    doSomething().then(handleResult).catch(handleException);
    

我更喜欢使用第二种，因为如果 _handleResult_ 不小心也抛出了异常，第二种依然能捕获到错误，而第一种则不能。

未处理的 Promise 异常会“冒泡”到全局，从而产生一些让人不愉快的打印日志。在 Node.js 环境，我们可以通过监听 `process` 的事件来捕获这种异常：

    process.on('unhandledRejection', (reason, promise) => {
        console.log(reason);
    });
    

这种做法几乎是每一个生产环境中的应用程序所必须做的。对应浏览器环境则是：

    window.addEventListener('unhandledrejection', (reason, promise) => {
        console.log(reason);
    });
    

有的异步任务我们希望可以忽略错误，不被以上代码所捕获，我看到有很多人图省事都这么写：

    doSomething().catch(); // ❌
    

以为这样是加了一个 catch，阻止异常抛到全局，但是这样和 `then` 省略第二个参数是一个效果。事实上，在 ECMAScript 规范中，**`catch 本质就是 then 缺少第一个参数而已`**。所以，你至少应该这样写：

    doSomething().catch(e => e); // ✅
    

抛到全局的不止是 Promise，Error 也会，比如 Node.js 上的 `uncaughtException`：

    process.on('uncaughtException', (err, origin) => {});
    

或者浏览器上的：

    window.addEventlistener('error', (err) => {});
    

我相信大家在各自的业务上都做过线上页面异常监控的事情，无论你是直接用的现成的打点 SDK，还是自己实现，都是以上面的这种原理来实现的。但这只是捕获错误的最后一道关卡，你的业务逻辑不应该依赖这个机制。

像 window 环境以事件作为捕获错误的方法，在很多场景中都有应用，比如说 `XMLHttpRequest` 就是一个典型：

    xhr.addEventListener('error', err => {})
    // 或者
    xhr.onerror = err => {};
    

以上我们讲到了这么多种错误的捕获方式，那么如果你来编写一个应用程序，又该如何选择呢？我这里仅给出我自己的建议，大家可以根据自己业务的实际情况来变通。

*   **如果你编写的是一个被调用的模块，如 SDK，那么：**
    *   **调用的函数执行后就能得到结果的，异步的就返回 Promise，该函数可以直接抛出异常；**
    *   **如果模块是持续运行的，那么就设计为通过事件报告异常。**
*   **如果你编写的是面向用户的终端程序，如网页，**
    *   **在用户交互入口处捕获错误并给用户以反馈，函数调用链路上尽量少用或不用捕获异常。**

我来举一个现实的例子，我们做头像上传，首先要选择本地图片，然后做文件校验，接着做尺寸裁剪，最后再上传到服务器。每一个环节都有可能发生错误。

![image.png](https://p1-juejin.byteimg.com/tos-cn-i-k3u1fbpfcp/60006307c99e476898139857f0c04d41~tplv-k3u1fbpfcp-jj-mark:1600:0:0:0:q75.image#?w=3648&h=1828&s=300445&e=png&b=ffffff)

文件校验和图片裁剪这两个环节，是在同一个执行流中的，也就是上一个环节的输出就是下一个环节的输入。只要执行流结束，就能立即得到结果。也正是由于它们是“串行”的，一处异常则整个任务就失败。

这种场景我更建议只在执行过程的入口处加上一次 `try...catch`，各个环节自身都不加异常捕获，也尽量不要有任何的默认值，把最真实的执行情况反馈给用户侧。

在这个 `try...catch` 里，你可以根据错误信息的不同，采取不同的措施。那么对于图像上传这个阶段，由于它的耗时更长，并且逻辑更内聚（有明显的内部状态机），常常被设计成多个操作入口的 API，那就可以用事件的方式来报告错误。

以上的策略不是绝对的，不同的错误捕获方法常常可以相互转换，但核心原则还是要保证**用户操作有反馈**，我们既既不能不考虑出错的可能，也不能到处都捕获异常。

小结
--

ECMAScript 定义了六种 Error 子类型，它们承载的信息基本都是一样的，只有在 name 上稍稍体现了一些差异性。所以关于每种错误会在什么时候抛出，大家了解即可，平时也很少需要识别不同的错误类。

在捕获错误的方式方法上，我们除了技术细节外，更应该关注的是“设计模式”，如何以较低的成本保障错误上报通道的顺畅，以及用户交互体验的完备性。

保障程序的健壮性不应该偏执一端，我们应该在尽可能掌握什么时候会报错上下功夫，而不是野蛮地、反复地封锁住错误，这样效果适得其反。